<?xml version="1.0" ?>
<robot name="two_link_pendulum">

  <link name="base_link">
    <inertial>
      <mass value="1.0" />
      <origin xyz="0 0 0" />
      <inertia ixx="0.1" ixy="0.0" ixz="0.0" iyy="0.1" iyz="0.0" izz="0.1"/>
    </inertial>
    <visual>
      <geometry>
        <box size="0.05 0.05 0.05"/>
      </geometry>
    </visual>
  </link>

  <link name="link1">
    <inertial>
      <mass value="1.0" />
      <origin xyz="0 0 0.25" />
      <inertia ixx="0.1" ixy="0.0" ixz="0.0" iyy="0.1" iyz="0.0" izz="0.1"/>
    </inertial>
    <visual>
      <geometry>
        <cylinder length="0.5" radius="0.05"/>
      </geometry>
    </visual>
  </link>

  <joint name="joint1" type="revolute">
    <parent link="base_link"/>
    <child link="link1"/>
    <origin xyz="0 0 0" rpy="0 0 0"/>
    <axis xyz="0 1 0"/>
    <limit lower="-3.14" upper="3.14" effort="10.0" velocity="1.0"/>
  </joint>

  <link name="link2">
    <inertial>
      <mass value="1.0" />
      <origin xyz="0 0 0.25" />
      <inertia ixx="0.1" ixy="0.0" ixz="0.0" iyy="0.1" iyz="0.0" izz="0.1"/>
    </inertial>
    <visual>
      <geometry>
        <cylinder length="0.5" radius="0.05"/>
      </geometry>
    </visual>
  </link>

  <joint name="joint2" type="revolute">
    <parent link="link1"/>
    <child link="link2"/>
    <origin xyz="0 0 0.5" rpy="0 0 0"/>
    <axis xyz="0 1 0"/>
    <limit lower="-3.14" upper="3.14" effort="10.0" velocity="1.0"/>
  </joint>

</robot>
